<?xml version="1.0"?>
<robot xmlns:xacro="http://www.ros.org/wiki/xacro">

    <joint name="front_left_steering_joint" type="revolute">
        <parent link="base_link"/>
        <child link="front_left_steering_link"/>
        <origin xyz="0.15 0.175 0"/>
        <axis xyz="0 0 1"/>
        <limit lower="-0.5236" upper="0.5236" effort="10" velocity="1.0"/>
    </joint>

    <link name="front_left_steering_link"/>

    <joint name="front_right_steering_joint" type="revolute">
        <parent link="base_link"/>
        <child link="front_right_steering_link"/>
        <origin xyz="0.15 -0.175 0"/>
        <axis xyz="0 0 1"/>
        <limit lower="-0.5236" upper="0.5236" effort="10" velocity="1.0"/>
    </joint>

    <link name="front_right_steering_link"/>

</robot>
